Workbook

Sheet Python Outputs -->

Sheet qxRatesPivot
A1: Age | B1: 1910 | C1: 1911 | D1: 1912 | E1: 1913 | F1: 1914 | G1: 1915 | H1: 1916 | I1: 1917 | J1: 1918 | K1: 1919 | L1: 1920 | M1: 1921 | N1: 1922 | O1: 1923 | P1: 1924 | Q1: 1925 | R1: 1926 | S1: 1927 | T1: 1928 | U1: 1929 | V1: 1930 | W1: 1931 | X1: 1932 | Y1: 1933 | Z1: 1934 | AA1: 1935 | AB1: 1936 | AC1: 1937 | AD1: 1938 | AE1: 1939 | AF1: 1940 | AG1: 1941 | AH1: 1942 | AI1: 1943 | AJ1: 1944 | AK1: 1945 | AL1: 1946 | AM1: 1947 | AN1: 1948 | AO1: 1949 | AP1: 1950 | AQ1: 1951 | AR1: 1952 | AS1: 1953 | AT1: 1954 | AU1: 1955 | AV1: 1956 | AW1: 1957 | AX1: 1958 | AY1: 1959 | AZ1: 1960 | BA1: 1961 | BB1: 1962 | BC1: 1963 | BD1: 1964 | BE1: 1965 | BF1: 1966 | BG1: 1967 | BH1: 1968 | BI1: 1969 | BJ1: 1970 | BK1: 1971 | BL1: 1972 | BM1: 1973 | BN1: 1974 | BO1: 1975 | BP1: 1976 | BQ1: 1977 | BR1: 1978 | BS1: 1979 | BT1: 1980 | BU1: 1981 | BV1: 1982 | BW1: 1983 | BX1: 1984 | BY1: 1985 | BZ1: 1986 | CA1: 1987 | CB1: 1988 | CC1: 1989 | CD1: 1990 | CE1: 1991 | CF1: 1992 | CG1: 1993 | CH1: 1994 | CI1: 1995 | CJ1: 1996 | CK1: 1997 | CL1: 1998 | CM1: 1999 | CN1: 2000 | CO1: 2001 | CP1: 2002 | CQ1: 2003 | CR1: 2004 | CS1: 2005 | CT1: 2006 | CU1: 2007 | CV1: 2008 | CW1: 2009 | CX1: 2010 | CY1: 2011 | CZ1: 2012 | DA1: 2013 | DB1: 2014 | DC1: 2015 | DD1: 2016 | DE1: 2017 | DF1: 2018 | DG1: 2019 | DH1: 2020 | DI1: 2021
A2: 0 | B2: 0.16112 | C2: 0.172525 | D2: 0.14791 | E2: 0.147737 | F2: 0.141998 | G2: 0.163751 | H2: 0.16125 | I2: 0.158625 | J2: 0.209396 | K2: 0.174798 | L2: 0.154567 | M2: 0.151863 | N2: 0.138223 | O2: 0.132857 | P2: 0.132565 | Q2: 0.129533 | R2: 0.135582 | S2: 0.130365 | T2: 0.128922 | U2: 0.132866 | V2: 0.116718 | W2: 0.116968 | X2: 0.116975 | Y2: 0.107722 | Z2: 0.104169 | AA2: 0.108249 | AB2: 0.104616 | AC2: 0.119258 | AD2: 0.115359 | AE2: 0.104213 | AF2: 0.109852 | AG2: 0.114689 | AH2: 0.122412 | AI2: 0.121313 | AJ2: 0.107206 | AK2: 0.111331 | AL2: 0.104257 | AM2: 0.088689 | AN2: 0.076444 | AO2: 0.074329 | AP2: 0.066844 | AQ2: 0.067505 | AR2: 0.065909 | AS2: 0.060512 | AT2: 0.056369 | AU2: 0.052613 | AV2: 0.050542 | AW2: 0.052437 | AX2: 0.049783 | AY2: 0.047916 | AZ2: 0.045486 | BA2: 0.043112 | BB2: 0.043706 | BC2: 0.041931 | BD2: 0.0382 | BE2: 0.036379 | BF2: 0.035406 | BG2: 0.033628 | BH2: 0.033092 | BI2: 0.031807 | BJ2: 0.029877 | BK2: 0.029501 | BL2: 0.027526 | BM2: 0.026466 | BN2: 0.023349 | BO2: 0.02089 | BP2: 0.019235 | BQ2: 0.017897 | BR2: 0.016959 | BS2: 0.015382 | BT2: 0.014495 | BU2: 0.014188 | BV2: 0.013115 | BW2: 0.011981 | BX2: 0.011184 | BY2: 0.010322 | BZ2: 0.009958 | CA2: 0.009743 | CB2: 0.009358 | CC2: 0.00862 | CD2: 0.008189 | CE2: 0.008461 | CF2: 0.008284 | CG2: 0.006979 | CH2: 0.00647 | CI2: 0.006191 | CJ2: 0.006151 | CK2: 0.005491 | CL2: 0.005401 | CM2: 0.005151 | CN2: 0.004553 | CO2: 0.004656 | CP2: 0.004443 | CQ2: 0.003752 | CR2: 0.003836 | CS2: 0.003586 | CT2: 0.003461 | CU2: 0.003317 | CV2: 0.003349 | CW2: 0.003445 | CX2: 0.003186 | CY2: 0.003088 | CZ2: 0.002984 | DA2: 0.002913 | DB2: 0.002756 | DC2: 0.002863 | DD2: 0.002813 | DE2: 0.00287 | DF2: 0.002844 | DG2: 0.002496 | DH2: 0.002462 | DI2: 0.002584
A3: 1 | B3: 0.065061 | C3: 0.074446 | D3: 0.058148 | E3: 0.063191 | F3: 0.052998 | G3: 0.067914 | H3: 0.073304 | I3: 0.061814 | J3: 0.11136 | K3: 0.064884 | L3: 0.065747 | M3: 0.057538 | N3: 0.050515 | O3: 0.050925 | P3: 0.044157 | Q3: 0.049422 | R3: 0.053586 | S3: 0.045433 | T3: 0.046637 | U3: 0.045524 | V3: 0.040439 | W3: 0.039584 | X3: 0.039752 | Y3: 0.033721 | Z3: 0.035596 | AA3: 0.035611 | AB3: 0.033651 | AC3: 0.038863 | AD3: 0.035697 | AE3: 0.031798 | AF3: 0.028945 | AG3: 0.032977 | AH3: 0.03047 | AI3: 0.031708 | AJ3: 0.024378 | AK3: 0.027247 | AL3: 0.028862 | AM3: 0.018766 | AN3: 0.014578 | AO3: 0.014628 | AP3: 0.011264 | AQ3: 0.011039 | AR3: 0.010058 | AS3: 0.008034 | AT3: 0.006469 | AU3: 0.005594 | AV3: 0.0052 | AW3: 0.005531 | AX3: 0.005379 | AY3: 0.004675 | AZ3: 0.004333 | BA3: 0.003672 | BB3: 0.003657 | BC3: 0.003243 | BD3: 0.002832 | BE3: 0.002571 | BF3: 0.002373 | BG3: 0.002126 | BH3: 0.00206 | BI3: 0.00197 | BJ3: 0.001794 | BK3: 0.0015 | BL3: 0.001387 | BM3: 0.001206 | BN3: 0.001064 | BO3: 0.000957 | BP3: 0.000925 | BQ3: 0.000881 | BR3: 0.000864 | BS3: 0.00082 | BT3: 0.000842 | BU3: 0.00075 | BV3: 0.000671 | BW3: 0.00072 | BX3: 0.000525 | BY3: 0.00055 | BZ3: 0.000501 | CA3: 0.000595 | CB3: 0.000506 | CC3: 0.000424 | CD3: 0.000434 | CE3: 0.000496 | CF3: 0.000497 | CG3: 0.000482 | CH3: 0.000409 | CI3: 0.000448 | CJ3: 0.000425 | CK3: 0.00042 | CL3: 0.000295 | CM3: 0.000309 | CN3: 0.000308 | CO3: 0.000296 | CP3: 0.000295 | CQ3: 0.00025 | CR3: 0.000258 | CS3: 0.000213 | CT3: 0.000237 | CU3: 0.000224 | CV3: 0.000197 | CW3: 0.000229 | CX3: 0.000213 | CY3: 0.000195 | CZ3: 0.000217 | DA3: 0.000202 | DB3: 0.000155 | DC3: 0.000194 | DD3: 0.000171 | DE3: 0.000201 | DF3: 0.000209 | DG3: 0.000161 | DH3: 0.000147 | DI3: 0.000165
A4: 2 | B4: 0.030173 | C4: 0.029636 | D4: 0.026244 | E4: 0.026626 | F4: 0.022532 | G4: 0.027426 | H4: 0.031933 | I4: 0.026144 | J4: 0.058577 | K4: 0.030002 | L4: 0.028887 | M4: 0.023744 | N4: 0.022017 | O4: 0.020045 | P4: 0.017019 | Q4: 0.019359 | R4: 0.020429 | S4: 0.017119 | T4: 0.01697 | U4: 0.016321 | V4: 0.014078 | W4: 0.013059 | X4: 0.012898 | Y4: 0.012021 | Z4: 0.011333 | AA4: 0.011136 | AB4: 0.011065 | AC4: 0.011694 | AD4: 0.014606 | AE4: 0.009533 | AF4: 0.008549 | AG4: 0.009804 | AH4: 0.009529 | AI4: 0.010443 | AJ4: 0.008617 | AK4: 0.008641 | AL4: 0.009792 | AM4: 0.006863 | AN4: 0.005361 | AO4: 0.005023 | AP4: 0.003785 | AQ4: 0.003485 | AR4: 0.003406 | AS4: 0.003039 | AT4: 0.002487 | AU4: 0.00237 | AV4: 0.002218 | AW4: 0.002244 | AX4: 0.002167 | AY4: 0.002046 | AZ4: 0.001829 | BA4: 0.00164 | BB4: 0.001732 | BC4: 0.001506 | BD4: 0.001344 | BE4: 0.001286 | BF4: 0.001108 | BG4: 0.001088 | BH4: 0.001045 | BI4: 0.001063 | BJ4: 0.000964 | BK4: 0.000942 | BL4: 0.000812 | BM4: 0.000748 | BN4: 0.000611 | BO4: 0.000607 | BP4: 0.000561 | BQ4: 0.00051 | BR4: 0.000506 | BS4: 0.000483 | BT4: 0.000543 | BU4: 0.000433 | BV4: 0.000425 | BW4: 0.000469 | BX4: 0.000384 | BY4: 0.000366 | BZ4: 0.000325 | CA4: 0.000312 | CB4: 0.000338 | CC4: 0.000327 | CD4: 0.00028 | CE4: 0.000317 | CF4: 0.000343 | CG4: 0.000423 | CH4: 0.000355 | CI4: 0.000322 | CJ4: 0.000249 | CK4: 0.000294 | CL4: 0.00021 | CM4: 0.000167 | CN4: 0.000188 | CO4: 0.000221 | CP4: 0.000209 | CQ4: 0.000155 | CR4: 0.000158 | CS4: 0.000143 | CT4: 0.000132 | CU4: 0.00015 | CV4: 0.000174 | CW4: 0.000136 | CX4: 0.000129 | CY4: 0.000124 | CZ4: 0.000137 | DA4: 0.000151 | DB4: 0.000132 | DC4: 0.000119 | DD4: 8.1e-05 | DE4: 0.000137 | DF4: 0.000131 | DG4: 0.000107 | DH4: 0.000108 | DI4: 0.000123
A5: 3 | B5: 0.016491 | C5: 0.016769 | D5: 0.014495 | E5: 0.015509 | F5: 0.012636 | G5: 0.015068 | H5: 0.017717 | I5: 0.015218 | J5: 0.037842 | K5: 0.016921 | L5: 0.016206 | M5: 0.012465 | N5: 0.012578 | O5: 0.01145 | P5: 0.011151 | Q5: 0.010741 | R5: 0.010485 | S5: 0.009354 | T5: 0.009072 | U5: 0.008588 | V5: 0.007716 | W5: 0.007423 | X5: 0.006961 | Y5: 0.006999 | Z5: 0.006445 | AA5: 0.00626 | AB5: 0.006083 | AC5: 0.00633 | AD5: 0.004457 | AE5: 0.005185 | AF5: 0.004953 | AG5: 0.005387 | AH5: 0.005065 | AI5: 0.005757 | AJ5: 0.005043 | AK5: 0.004768 | AL5: 0.005003 | AM5: 0.003838 | AN5: 0.002996 | AO5: 0.002933 | AP5: 0.002223 | AQ5: 0.002072 | AR5: 0.00198 | AS5: 0.001783 | AT5: 0.001648 | AU5: 0.00153 | AV5: 0.001415 | AW5: 0.001585 | AX5: 0.001391 | AY5: 0.001394 | AZ5: 0.001239 | BA5: 0.001156 | BB5: 0.0011 | BC5: 0.001065 | BD5: 0.000935 | BE5: 0.000905 | BF5: 0.000771 | BG5: 0.000765 | BH5: 0.000803 | BI5: 0.000723 | BJ5: 0.000706 | BK5: 0.000645 | BL5: 0.000593 | BM5: 0.000609 | BN5: 0.000491 | BO5: 0.000483 | BP5: 0.000447 | BQ5: 0.000435 | BR5: 0.000432 | BS5: 0.000378 | BT5: 0.000432 | BU5: 0.000368 | BV5: 0.000328 | BW5: 0.000364 | BX5: 0.000327 | BY5: 0.000311 | BZ5: 0.000246 | CA5: 0.000266 | CB5: 0.000268 | CC5: 0.000225 | CD5: 0.00023 | CE5: 0.000253 | CF5: 0.000241 | CG5: 0.000364 | CH5: 0.000299 | CI5: 0.000253 | CJ5: 0.000205 | CK5: 0.000283 | CL5: 0.000206 | CM5: 0.000158 | CN5: 0.000139 | CO5: 0.000165 | CP5: 0.000177 | CQ5: 0.000148 | CR5: 0.000124 | CS5: 0.000151 | CT5: 0.000113 | CU5: 0.000118 | CV5: 0.000155 | CW5: 8.9e-05 | CX5: 0.000129 | CY5: 0.000111 | CZ5: 8.5e-05 | DA5: 0.0001 | DB5: 0.00012 | DC5: 9.9e-05 | DD5: 9e-05 | DE5: 9.5e-05 | DF5: 8.6e-05 | DG5: 0.000101 | DH5: 7.2e-05 | DI5: 9.2e-05
A6: 4 | B6: 0.011219 | C6: 0.011249 | D6: 0.010001 | E6: 0.009948 | F6: 0.009014 | G6: 0.010047 | H6: 0.012161 | I6: 0.010661 | J6: 0.028605 | K6: 0.012742 | L6: 0.011222 | M6: 0.008448 | N6: 0.007879 | O6: 0.007981 | P6: 0.00779 | Q6: 0.007947 | R6: 0.007216 | S6: 0.006144 | T6: 0.006141 | U6: 0.005826 | V6: 0.005372 | W6: 0.004983 | X6: 0.004747 | Y6: 0.004584 | Z6: 0.004401 | AA6: 0.004448 | AB6: 0.003954 | AC6: 0.004376 | AD6: 0.003004 | AE6: 0.003637 | AF6: 0.003425 | AG6: 0.003845 | AH6: 0.003835 | AI6: 0.00407 | AJ6: 0.003816 | AK6: 0.003381 | AL6: 0.003468 | AM6: 0.00262 | AN6: 0.002158 | AO6: 0.002104 | AP6: 0.001603 | AQ6: 0.001546 | AR6: 0.001522 | AS6: 0.0014 | AT6: 0.001218 | AU6: 0.001209 | AV6: 0.001091 | AW6: 0.001177 | AX6: 0.001047 | AY6: 0.000965 | AZ6: 0.000967 | BA6: 0.000844 | BB6: 0.000844 | BC6: 0.000899 | BD6: 0.000806 | BE6: 0.000704 | BF6: 0.000661 | BG6: 0.000634 | BH6: 0.000648 | BI6: 0.000604 | BJ6: 0.000567 | BK6: 0.000571 | BL6: 0.000541 | BM6: 0.000497 | BN6: 0.000412 | BO6: 0.000448 | BP6: 0.000402 | BQ6: 0.000348 | BR6: 0.000353 | BS6: 0.00032 | BT6: 0.000339 | BU6: 0.000277 | BV6: 0.000274 | BW6: 0.000294 | BX6: 0.000282 | BY6: 0.000272 | BZ6: 0.000213 | CA6: 0.000258 | CB6: 0.000212 | CC6: 0.000204 | CD6: 0.00022 | CE6: 0.000203 | CF6: 0.000186 | CG6: 0.000227 | CH6: 0.000241 | CI6: 0.000164 | CJ6: 0.000219 | CK6: 0.000197 | CL6: 0.000138 | CM6: 0.000134 | CN6: 0.000138 | CO6: 0.000163 | CP6: 0.000149 | CQ6: 0.000134 | CR6: 0.000119 | CS6: 0.000117 | CT6: 0.000148 | CU6: 9.8e-05 | CV6: 8.7e-05 | CW6: 0.000107 | CX6: 0.000105 | CY6: 9.4e-05 | CZ6: 9.2e-05 | DA6: 8.3e-05 | DB6: 9.1e-05 | DC6: 8.9e-05 | DD6: 6.1e-05 | DE6: 8.5e-05 | DF6: 8.7e-05 | DG6: 7.7e-05 | DH6: 7.5e-05 | DI6: 6.5e-05
A7: 5 | B7: 0.00767 | C7: 0.007724 | D7: 0.006728 | E7: 0.007412 | F7: 0.006138 | G7: 0.007107 | H7: 0.008589 | I7: 0.007912 | J7: 0.0209 | K7: 0.009012 | L7: 0.008131 | M7: 0.005783 | N7: 0.005452 | O7: 0.005172 | P7: 0.005643 | Q7: 0.005773 | R7: 0.005363 | S7: 0.004531 | T7: 0.004379 | U7: 0.004188 | V7: 0.003843 | W7: 0.003607 | X7: 0.00358 | Y7: 0.003529 | Z7: 0.003313 | AA7: 0.003413 | AB7: 0.003151 | AC7: 0.003134 | AD7: 0.003015 | AE7: 0.002749 | AF7: 0.002502 | AG7: 0.0028 | AH7: 0.002955 | AI7: 0.003413 | AJ7: 0.003111 | AK7: 0.002766 | AL7: 0.002558 | AM7: 0.002053 | AN7: 0.00172 | AO7: 0.001582 | AP7: 0.001263 | AQ7: 0.001178 | AR7: 0.001181 | AS7: 0.001084 | AT7: 0.000921 | AU7: 0.000975 | AV7: 0.00087 | AW7: 0.000898 | AX7: 0.0009 | AY7: 0.000875 | AZ7: 0.000744 | BA7: 0.000765 | BB7: 0.000688 | BC7: 0.000692 | BD7: 0.000603 | BE7: 0.000593 | BF7: 0.00059 | BG7: 0.000526 | BH7: 0.000546 | BI7: 0.000547 | BJ7: 0.000514 | BK7: 0.000489 | BL7: 0.000437 | BM7: 0.000482 | BN7: 0.000376 | BO7: 0.000364 | BP7: 0.000358 | BQ7: 0.000317 | BR7: 0.000293 | BS7: 0.000305 | BT7: 0.000331 | BU7: 0.000273 | BV7: 0.000265 | BW7: 0.000234 | BX7: 0.000208 | BY7: 0.000202 | BZ7: 0.000191 | CA7: 0.000205 | CB7: 0.000219 | CC7: 0.000182 | CD7: 0.000199 | CE7: 0.000236 | CF7: 0.000195 | CG7: 0.000214 | CH7: 0.0002 | CI7: 0.000223 | CJ7: 0.000189 | CK7: 0.000175 | CL7: 0.00011 | CM7: 0.00014 | CN7: 0.000126 | CO7: 0.000124 | CP7: 0.000126 | CQ7: 0.000101 | CR7: 9e-05 | CS7: 0.000109 | CT7: 8.9e-05 | CU7: 7.9e-05 | CV7: 7.9e-05 | CW7: 8.1e-05 | CX7: 8.4e-05 | CY7: 9.8e-05 | CZ7: 8.6e-05 | DA7: 6.5e-05 | DB7: 7.1e-05 | DC7: 6.3e-05 | DD7: 6.6e-05 | DE7: 7.6e-05 | DF7: 9.3e-05 | DG7: 4.4e-05 | DH7: 6.5e-05 | DI7: 6.6e-05
A8: 6 | B8: 0.006037 | C8: 0.006268 | D8: 0.005306 | E8: 0.00538 | F8: 0.005109 | G8: 0.005405 | H8: 0.006558 | I8: 0.0061 | J8: 0.017864 | K8: 0.007267 | L8: 0.00635 | M8: 0.004904 | N8: 0.004178 | O8: 0.003954 | P8: 0.003936 | Q8: 0.004617 | R8: 0.004323 | S8: 0.003974 | T8: 0.003498 | U8: 0.003418 | V8: 0.003121 | W8: 0.00292 | X8: 0.002922 | Y8: 0.002786 | Z8: 0.002665 | AA8: 0.002673 | AB8: 0.002479 | AC8: 0.002589 | AD8: 0.002556 | AE8: 0.002389 | AF8: 0.002117 | AG8: 0.002285 | AH8: 0.002444 | AI8: 0.003109 | AJ8: 0.002848 | AK8: 0.002477 | AL8: 0.002104 | AM8: 0.001785 | AN8: 0.001434 | AO8: 0.001347 | AP8: 0.001057 | AQ8: 0.000993 | AR8: 0.000962 | AS8: 0.00095 | AT8: 0.00081 | AU8: 0.000833 | AV8: 0.0008 | AW8: 0.000768 | AX8: 0.000788 | AY8: 0.000701 | AZ8: 0.00069 | BA8: 0.000672 | BB8: 0.000641 | BC8: 0.000629 | BD8: 0.000573 | BE8: 0.000528 | BF8: 0.000493 | BG8: 0.00049 | BH8: 0.000466 | BI8: 0.000453 | BJ8: 0.000455 | BK8: 0.000446 | BL8: 0.000445 | BM8: 0.000422 | BN8: 0.000365 | BO8: 0.000408 | BP8: 0.000346 | BQ8: 0.000354 | BR8: 0.000336 | BS8: 0.000258 | BT8: 0.000342 | BU8: 0.000259 | BV8: 0.000283 | BW8: 0.000244 | BX8: 0.000224 | BY8: 0.000214 | BZ8: 0.00021 | CA8: 0.000205 | CB8: 0.000174 | CC8: 0.000172 | CD8: 0.000147 | CE8: 0.000194 | CF8: 0.000162 | CG8: 0.00024 | CH8: 0.000194 | CI8: 0.000222 | CJ8: 0.000153 | CK8: 0.000192 | CL8: 0.000139 | CM8: 0.000139 | CN8: 0.000137 | CO8: 0.000115 | CP8: 0.000147 | CQ8: 0.000107 | CR8: 9.5e-05 | CS8: 9.5e-05 | CT8: 0.000106 | CU8: 9.9e-05 | CV8: 8.6e-05 | CW8: 8.1e-05 | CX8: 8.3e-05 | CY8: 7.8e-05 | CZ8: 6.9e-05 | DA8: 6.1e-05 | DB8: 8.8e-05 | DC8: 6.2e-05 | DD8: 8.6e-05 | DE8: 9.3e-05 | DF8: 6.2e-05 | DG8: 6.8e-05 | DH8: 7.3e-05 | DI8: 5.9e-05
A9: 7 | B9: 0.004554 | C9: 0.004925 | D9: 0.004173 | E9: 0.004141 | F9: 0.004006 | G9: 0.004465 | H9: 0.004877 | I9: 0.005009 | J9: 0.014379 | K9: 0.005818 | L9: 0.00512 | M9: 0.004058 | N9: 0.003371 | O9: 0.002982 | P9: 0.003254 | Q9: 0.003368 | R9: 0.003359 | S9: 0.003144 | T9: 0.003038 | U9: 0.002742 | V9: 0.0025 | W9: 0.002506 | X9: 0.002417 | Y9: 0.002323 | Z9: 0.002306 | AA9: 0.002301 | AB9: 0.002115 | AC9: 0.00225 | AD9: 0.00211 | AE9: 0.001925 | AF9: 0.001815 | AG9: 0.002091 | AH9: 0.002067 | AI9: 0.002618 | AJ9: 0.002631 | AK9: 0.002316 | AL9: 0.0019 | AM9: 0.001537 | AN9: 0.001267 | AO9: 0.00113 | AP9: 0.00095 | AQ9: 0.000892 | AR9: 0.000811 | AS9: 0.000863 | AT9: 0.000716 | AU9: 0.000729 | AV9: 0.000741 | AW9: 0.00075 | AX9: 0.000694 | AY9: 0.000585 | AZ9: 0.000582 | BA9: 0.000541 | BB9: 0.000563 | BC9: 0.000601 | BD9: 0.000533 | BE9: 0.000509 | BF9: 0.000425 | BG9: 0.000431 | BH9: 0.000397 | BI9: 0.000373 | BJ9: 0.000439 | BK9: 0.000413 | BL9: 0.0004 | BM9: 0.000359 | BN9: 0.000373 | BO9: 0.000302 | BP9: 0.000329 | BQ9: 0.000341 | BR9: 0.000288 | BS9: 0.00025 | BT9: 0.000325 | BU9: 0.000245 | BV9: 0.000227 | BW9: 0.000221 | BX9: 0.000219 | BY9: 0.000198 | BZ9: 0.000196 | CA9: 0.000179 | CB9: 0.000187 | CC9: 0.000164 | CD9: 0.000166 | CE9: 0.000159 | CF9: 0.000166 | CG9: 0.000183 | CH9: 0.000185 | CI9: 0.000179 | CJ9: 0.000187 | CK9: 0.000164 | CL9: 0.00013 | CM9: 0.00011 | CN9: 0.000107 | CO9: 9.4e-05 | CP9: 0.000128 | CQ9: 0.000114 | CR9: 8.4e-05 | CS9: 9.8e-05 | CT9: 8.1e-05 | CU9: 9.4e-05 | CV9: 6.8e-05 | CW9: 0.000107 | CX9: 8.2e-05 | CY9: 7.4e-05 | CZ9: 7e-05 | DA9: 9.2e-05 | DB9: 5.6e-05 | DC9: 5.4e-05 | DD9: 6e-05 | DE9: 7.2e-05 | DF9: 5.5e-05 | DG9: 4.5e-05 | DH9: 4.6e-05 | DI9: 5.7e-05
A10: 8 | B10: 0.003767 | C10: 0.003767 | D10: 0.003412 | E10: 0.003535 | F10: 0.003124 | G10: 0.003644 | H10: 0.004261 | I10: 0.004178 | J10: 0.013617 | K10: 0.005005 | L10: 0.004493 | M10: 0.003224 | N10: 0.00296 | O10: 0.002633 | P10: 0.002565 | Q10: 0.002672 | R10: 0.0027 | S10: 0.00254 | T10: 0.002616 | U10: 0.00254 | V10: 0.002275 | W10: 0.002168 | X10: 0.002152 | Y10: 0.002078 | Z10: 0.001908 | AA10: 0.001952 | AB10: 0.001895 | AC10: 0.002027 | AD10: 0.001764 | AE10: 0.001666 | AF10: 0.001668 | AG10: 0.001792 | AH10: 0.001834 | AI10: 0.002585 | AJ10: 0.002541 | AK10: 0.002189 | AL10: 0.001669 | AM10: 0.001415 | AN10: 0.001062 | AO10: 0.000982 | AP10: 0.000802 | AQ10: 0.000784 | AR10: 0.000751 | AS10: 0.000695 | AT10: 0.000644 | AU10: 0.000623 | AV10: 0.00062 | AW10: 0.000654 | AX10: 0.000615 | AY10: 0.000602 | AZ10: 0.000533 | BA10: 0.000461 | BB10: 0.000516 | BC10: 0.000506 | BD10: 0.000449 | BE10: 0.000429 | BF10: 0.000407 | BG10: 0.000394 | BH10: 0.000408 | BI10: 0.000394 | BJ10: 0.000364 | BK10: 0.000381 | BL10: 0.000382 | BM10: 0.000354 | BN10: 0.000322 | BO10: 0.000333 | BP10: 0.000347 | BQ10: 0.000293 | BR10: 0.000281 | BS10: 0.000275 | BT10: 0.000285 | BU10: 0.000206 | BV10: 0.000225 | BW10: 0.00021 | BX10: 0.000221 | BY10: 0.000211 | BZ10: 0.000177 | CA10: 0.000192 | CB10: 0.000139 | CC10: 0.000159 | CD10: 0.000154 | CE10: 0.000193 | CF10: 0.000181 | CG10: 0.000184 | CH10: 0.000148 | CI10: 0.000167 | CJ10: 0.000163 | CK10: 0.000129 | CL10: 0.000118 | CM10: 8.1e-05 | CN10: 0.00014 | CO10: 0.0001 | CP10: 0.000135 | CQ10: 8.9e-05 | CR10: 9e-05 | CS10: 7.4e-05 | CT10: 7.8e-05 | CU10: 0.000101 | CV10: 7.4e-05 | CW10: 6.9e-05 | CX10: 5.6e-05 | CY10: 8.6e-05 | CZ10: 6.3e-05 | DA10: 5.6e-05 | DB10: 6e-05 | DC10: 6.3e-05 | DD10: 8.3e-05 | DE10: 5.8e-05 | DF10: 6.3e-05 | DG10: 5.3e-05 | DH10: 5.4e-05 | DI10: 7.5e-05
A11: 9 | B11: 0.003235 | C11: 0.003364 | D11: 0.002937 | E11: 0.003026 | F11: 0.002708 | G11: 0.003119 | H11: 0.003625 | I11: 0.003875 | J11: 0.011524 | K11: 0.004349 | L11: 0.003946 | M11: 0.003248 | N11: 0.002618 | O11: 0.002689 | P11: 0.002376 | Q11: 0.002297 | R11: 0.00215 | S11: 0.002225 | T11: 0.002425 | U11: 0.002222 | V11: 0.002125 | W11: 0.001857 | X11: 0.001931 | Y11: 0.001916 | Z11: 0.001843 | AA11: 0.001803 | AB11: 0.001653 | AC11: 0.00184 | AD11: 0.001533 | AE11: 0.001604 | AF11: 0.001556 | AG11: 0.001611 | AH11: 0.001772 | AI11: 0.00251 | AJ11: 0.002525 | AK11: 0.002093 | AL11: 0.001651 | AM11: 0.00138 | AN11: 0.00108 | AO11: 0.000963 | AP11: 0.000731 | AQ11: 0.000705 | AR11: 0.000688 | AS11: 0.00068 | AT11: 0.000594 | AU11: 0.000554 | AV11: 0.000587 | AW11: 0.000626 | AX11: 0.000507 | AY11: 0.000547 | AZ11: 0.000445 | BA11: 0.000468 | BB11: 0.000476 | BC11: 0.00048 | BD11: 0.000418 | BE11: 0.000439 | BF11: 0.0004 | BG11: 0.000363 | BH11: 0.000419 | BI11: 0.000382 | BJ11: 0.000348 | BK11: 0.000322 | BL11: 0.00034 | BM11: 0.000355 | BN11: 0.000313 | BO11: 0.000292 | BP11: 0.000265 | BQ11: 0.000293 | BR11: 0.000272 | BS11: 0.000263 | BT11: 0.000317 | BU11: 0.000253 | BV11: 0.000224 | BW11: 0.000212 | BX11: 0.00019 | BY11: 0.000196 | BZ11: 0.000169 | CA11: 0.000167 | CB11: 0.000169 | CC11: 0.000162 | CD11: 0.000181 | CE11: 0.000129 | CF11: 0.000148 | CG11: 0.000185 | CH11: 0.00018 | CI11: 0.000118 | CJ11: 0.000151 | CK11: 0.000127 | CL11: 0.000155 | CM11: 0.000104 | CN11: 0.000122 | CO11: 0.000112 | CP11: 0.000123 | CQ11: 8.7e-05 | CR11: 8.3e-05 | CS11: 9.7e-05 | CT11: 8.4e-05 | CU11: 7e-05 | CV11: 6.9e-05 | CW11: 9.4e-05 | CX11: 6.7e-05 | CY11: 8.6e-05 | CZ11: 6.2e-05 | DA11: 7.7e-05 | DB11: 6.2e-05 | DC11: 6.7e-05 | DD11: 7.6e-05 | DE11: 7.9e-05 | DF11: 6.2e-05 | DG11: 6.1e-05 | DH11: 4.5e-05 | DI11: 3.5e-05
A12: 10 | B12: 0.002955 | C12: 0.003256 | D12: 0.002759 | E12: 0.002805 | F12: 0.00265 | G12: 0.003044 | H12: 0.003308 | I12: 0.003504 | J12: 0.011722 | K12: 0.003968 | L12: 0.00368 | M12: 0.002911 | N12: 0.002609 | O12: 0.002323 | P12: 0.002415 | Q12: 0.002339 | R12: 0.002221 | S12: 0.002086 | T12: 0.002 | U12: 0.002068 | V12: 0.001897 | W12: 0.001977 | X12: 0.001808 | Y12: 0.001735 | Z12: 0.001669 | AA12: 0.001677 | AB12: 0.001639 | AC12: 0.001731 | AD12: 0.00167 | AE12: 0.001567 | AF12: 0.001551 | AG12: 0.00151 | AH12: 0.001669 | AI12: 0.00257 | AJ12: 0.002467 | AK12: 0.002094 | AL12: 0.001566 | AM12: 0.001317 | AN12: 0.001069 | AO12: 0.000944 | AP12: 0.000728 | AQ12: 0.000704 | AR12: 0.000657 | AS12: 0.000648 | AT12: 0.000599 | AU12: 0.00054 | AV12: 0.000558 | AW12: 0.000633 | AX12: 0.000491 | AY12: 0.000496 | AZ12: 0.00049 | BA12: 0.000461 | BB12: 0.000439 | BC12: 0.000454 | BD12: 0.00043 | BE12: 0.000395 | BF12: 0.000332 | BG12: 0.000392 | BH12: 0.000377 | BI12: 0.00036 | BJ12: 0.000334 | BK12: 0.000327 | BL12: 0.000328 | BM12: 0.000358 | BN12: 0.000268 | BO12: 0.00028 | BP12: 0.000293 | BQ12: 0.000263 | BR12: 0.000276 | BS12: 0.000257 | BT12: 0.000254 | BU12: 0.000208 | BV12: 0.000192 | BW12: 0.000217 | BX12: 0.000197 | BY12: 0.000214 | BZ12: 0.0002 | CA12: 0.000191 | CB12: 0.000144 | CC12: 0.000147 | CD12: 0.000153 | CE12: 0.000141 | CF12: 0.000173 | CG12: 0.000168 | CH12: 0.000162 | CI12: 0.000158 | CJ12: 0.000137 | CK12: 0.000122 | CL12: 0.000134 | CM12: 0.000103 | CN12: 9.2e-05 | CO12: 0.000104 | CP12: 0.000122 | CQ12: 8.6e-05 | CR12: 7.5e-05 | CS12: 8.8e-05 | CT12: 6.3e-05 | CU12: 0.000103 | CV12: 8.2e-05 | CW12: 7.4e-05 | CX12: 6.9e-05 | CY12: 7.5e-05 | CZ12: 7.5e-05 | DA12: 6.7e-05 | DB12: 4.5e-05 | DC12: 5.2e-05 | DD12: 9.6e-05 | DE12: 9.1e-05 | DF12: 6.3e-05 | DG12: 7.4e-05 | DH12: 6.1e-05 | DI12: 7.4e-05
A13: 11 | B13: 0.002771 | C13: 0.00298 | D13: 0.002582 | E13: 0.002632 | F13: 0.002509 | G13: 0.00287 | H13: 0.003019 | I13: 0.003121 | J13: 0.010021 | K13: 0.003549 | L13: 0.003243 | M13: 0.002718 | N13: 0.002332 | O13: 0.002264 | P13: 0.002273 | Q13: 0.002216 | R13: 0.002157 | S13: 0.001906 | T13: 0.001826 | U13: 0.001937 | V13: 0.001763 | W13: 0.001791 | X13: 0.001889 | Y13: 0.001698 | Z13: 0.001702 | AA13: 0.001656 | AB13: 0.001509 | AC13: 0.001672 | AD13: 0.001612 | AE13: 0.001497 | AF13: 0.001463 | AG13: 0.001594 | AH13: 0.001665 | AI13: 0.00258 | AJ13: 0.002562 | AK13: 0.0021 | AL13: 0.001495 | AM13: 0.001306 | AN13: 0.001031 | AO13: 0.000913 | AP13: 0.00076 | AQ13: 0.000708 | AR13: 0.000628 | AS13: 0.000582 | AT13: 0.000582 | AU13: 0.000551 | AV13: 0.00052 | AW13: 0.000615 | AX13: 0.000469 | AY13: 0.000501 | AZ13: 0.000453 | BA13: 0.00049 | BB13: 0.000438 | BC13: 0.000486 | BD13: 0.000418 | BE13: 0.000379 | BF13: 0.000392 | BG13: 0.000399 | BH13: 0.000356 | BI13: 0.00034 | BJ13: 0.000342 | BK13: 0.000331 | BL13: 0.000349 | BM13: 0.000337 | BN13: 0.000302 | BO13: 0.000286 | BP13: 0.000315 | BQ13: 0.000307 | BR13: 0.000273 | BS13: 0.000302 | BT13: 0.000308 | BU13: 0.000211 | BV13: 0.000216 | BW13: 0.000222 | BX13: 0.000208 | BY13: 0.000195 | BZ13: 0.000208 | CA13: 0.00016 | CB13: 0.000171 | CC13: 0.000157 | CD13: 0.000159 | CE13: 0.000169 | CF13: 0.000168 | CG13: 0.000199 | CH13: 0.000138 | CI13: 0.000158 | CJ13: 0.000168 | CK13: 0.000176 | CL13: 0.000149 | CM13: 0.000125 | CN13: 0.000149 | CO13: 0.00013 | CP13: 9.7e-05 | CQ13: 0.000102 | CR13: 0.000111 | CS13: 6.4e-05 | CT13: 7.8e-05 | CU13: 8.6e-05 | CV13: 8.2e-05 | CW13: 0.000107 | CX13: 9.8e-05 | CY13: 7.4e-05 | CZ13: 5.7e-05 | DA13: 7e-05 | DB13: 7.4e-05 | DC13: 7.3e-05 | DD13: 5.9e-05 | DE13: 8.9e-05 | DF13: 7.2e-05 | DG13: 6.7e-05 | DH13: 6.7e-05 | DI13: 5.2e-05
... A112: 110 | B112: 1.621622 | C112: 4.21978 | D112: 0.957746 | E112: 2.289855 | F112: 1.525773 | G112: 1.115646 | H112: 4.179775 | I112: 6 | J112: 0.794118 | K112: 6 | L112: 0.681356 | M112: 2.093023 | N112: 2.413793 | O112: 1.340806 | P112: 6 | Q112: 2.184971 | R112: 1.372014 | S112: 6 | T112: 0.277992 | U112: 6 | V112: 2.4 | W112: 1.090909 | X112: 2 | Y112: 0.8 | Z112: 6 | AA112: 1.5 | AB112: 3 | AC112: 0.426 | AD112: 6 | AE112: 0.6 | AF112: 1.073892 | AG112: 1.2 | AH112: 3 | AI112: 6 | AJ112: 2.189573 | AK112: 4.264463 | AL112: 6 | AM112: 1.773913 | AN112: 2.241758 | AO112: 1.072539 | AP112: 0.420757 | AQ112: 1.339286 | AR112: 4.054054 | AS112: 1.013514 | AT112: 0.572519 | AU112: 1.384615 | AV112: 1.5 | AW112: 3 | AX112: 1.333333 | AY112: 1.2 | AZ112: 6 | BA112: 1.5 | BB112: 0.857143 | BC112: 0.75 | BD112: 6 | BE112: 3 | BF112: 0.428571 | BG112: 0.545455 | BH112: 1.2 | BI112: 1.2 | BJ112: 3 | BK112: 0.857143 | BL112: 1.5 | BM112: 6 | BN112: 2.4 | BO112: 0.461538 | BP112: 4 | BQ112: 0.428571 | BR112: 1.2 | BS112: 3 | BT112: 2.145411 | BU112: 3 | BV112: 1.090909 | BW112: 1.2 | BX112: 1 | BY112: 1.2 | BZ112: 3 | CA112: 0.36 | CB112: 0.461538 | CC112: 0.857143 | CD112: 0.272727 | CE112: 1.714286 | CF112: 0.375 | CG112: 1.2 | CH112: 0.352941 | CI112: 1.125 | CJ112: 0.62069 | CK112: 1.5 | CL112: 2 | CM112: 0.947368 | CN112: 0.387097 | CO112: 0.473684 | CP112: 0.916497 | CQ112: 0.861038 | CR112: 0.553889 | CS112: 1.444685 | CT112: 0.642055 | CU112: 1.138863 | CV112: 1.11576 | CW112: 0.832542 | CX112: 0.426935 | CY112: 1.27997 | CZ112: 1.07458 | DA112: 0.969682 | DB112: 0.787861 | DC112: 0.554246 | DD112: 0.979209 | DE112: 0.756383 | DF112: 0.571209 | DG112: 1.060474 | DH112: 0.985948 | DI112: 0.626453

Sheet qxLogCentered
A1: Age | B1: 1910 | C1: 1911 | D1: 1912 | E1: 1913 | F1: 1914 | G1: 1915 | H1: 1916 | I1: 1917 | J1: 1918 | K1: 1919 | L1: 1920 | M1: 1921 | N1: 1922 | O1: 1923 | P1: 1924 | Q1: 1925 | R1: 1926 | S1: 1927 | T1: 1928 | U1: 1929 | V1: 1930 | W1: 1931 | X1: 1932 | Y1: 1933 | Z1: 1934 | AA1: 1935 | AB1: 1936 | AC1: 1937 | AD1: 1938 | AE1: 1939 | AF1: 1940 | AG1: 1941 | AH1: 1942 | AI1: 1943 | AJ1: 1944 | AK1: 1945 | AL1: 1946 | AM1: 1947 | AN1: 1948 | AO1: 1949 | AP1: 1950 | AQ1: 1951 | AR1: 1952 | AS1: 1953 | AT1: 1954 | AU1: 1955 | AV1: 1956 | AW1: 1957 | AX1: 1958 | AY1: 1959 | AZ1: 1960 | BA1: 1961 | BB1: 1962 | BC1: 1963 | BD1: 1964 | BE1: 1965 | BF1: 1966 | BG1: 1967 | BH1: 1968 | BI1: 1969 | BJ1: 1970 | BK1: 1971 | BL1: 1972 | BM1: 1973 | BN1: 1974 | BO1: 1975 | BP1: 1976 | BQ1: 1977 | BR1: 1978 | BS1: 1979 | BT1: 1980 | BU1: 1981 | BV1: 1982 | BW1: 1983 | BX1: 1984 | BY1: 1985 | BZ1: 1986 | CA1: 1987 | CB1: 1988 | CC1: 1989 | CD1: 1990 | CE1: 1991 | CF1: 1992 | CG1: 1993 | CH1: 1994 | CI1: 1995 | CJ1: 1996 | CK1: 1997 | CL1: 1998 | CM1: 1999 | CN1: 2000 | CO1: 2001 | CP1: 2002 | CQ1: 2003 | CR1: 2004 | CS1: 2005 | CT1: 2006 | CU1: 2007 | CV1: 2008 | CW1: 2009 | CX1: 2010 | CY1: 2011 | CZ1: 2012 | DA1: 2013 | DB1: 2014 | DC1: 2015 | DD1: 2016 | DE1: 2017 | DF1: 2018 | DG1: 2019 | DH1: 2020 | DI1: 2021
A2: 0 | B2: 1.7799521 | C2: 1.8483448 | D2: 1.6944066 | E2: 1.6932363 | F2: 1.6536156 | G2: 1.7961496 | H2: 1.7807586 | I2: 1.7643456 | J2: 2.0420299 | K2: 1.8614337 | L2: 1.7384303 | M2: 1.7207815 | N2: 1.626671 | O2: 1.587076 | P2: 1.5848757 | Q2: 1.5617383 | R2: 1.6073793 | S2: 1.5681409 | T2: 1.5570102 | U2: 1.5871438 | V2: 1.4575634 | W2: 1.459703 | X2: 1.4597629 | Y2: 1.3773565 | Z2: 1.3438172 | AA2: 1.3822368 | AB2: 1.3480992 | AC2: 1.4790919 | AD2: 1.4458517 | AE2: 1.3442395 | AF2: 1.3969367 | AG2: 1.4400268 | AH2: 1.5051951 | AI2: 1.4961766 | AJ2: 1.3725549 | AK2: 1.4103104 | AL2: 1.3446617 | AM2: 1.1829385 | AN2: 1.0343611 | AO2: 1.0063038 | AP2: 0.9001642 | AQ2: 0.91000433 | AR2: 0.88607766 | AS2: 0.80064435 | AT2: 0.72972202 | AU2: 0.66076589 | AV2: 0.62060733 | AW2: 0.65741511 | AX2: 0.60547622 | AY2: 0.56725213 | AZ2: 0.51520724 | BA2: 0.46160404 | BB2: 0.47528805 | BC2: 0.43382807 | BD2: 0.34063817 | BE2: 0.29179434 | BF2: 0.26468395 | BG2: 0.21316171 | BH2: 0.19709422 | BI2: 0.15748905 | BJ2: 0.09489161 | BK2: 0.082226818 | BL2: 0.012933669 | BM2: -0.026336453 | BN2: -0.15164319 | BO2: -0.26292677 | BP2: -0.34546581 | BQ2: -0.41756424 | BR2: -0.47139868 | BS2: -0.56899935 | BT2: -0.62839358 | BU2: -0.64980081 | BV2: -0.72844073 | BW2: -0.81887528 | BX2: -0.88771316 | BY2: -0.9679198 | BZ2: -1.0038211 | CA2: -1.0256483 | CB2: -1.0659658 | CC2: -1.1481123 | CD2: -1.1994056 | CE2: -1.16673 | CF2: -1.1878714 | CG2: -1.3592917 | CH2: -1.4350212 | CI2: -1.4791007 | CJ2: -1.4855827 | CK2: -1.599087 | CL2: -1.6156132 | CM2: -1.6630065 | CN2: -1.786411 | CO2: -1.7640406 | CP2: -1.8108675 | CQ2: -1.9799083 | CR2: -1.9577672 | CS2: -2.02516 | CT2: -2.0606398 | CU2: -2.1031366 | CV2: -2.0935355 | CW2: -2.0652734 | CX2: -2.1434311 | CY2: -2.1746737 | CZ2: -2.2089327 | DA2: -2.2330139 | DB2: -2.288417 | DC2: -2.2503273 | DD2: -2.2679458 | DE2: -2.2478853 | DF2: -2.2569858 | DG2: -2.3875079 | DH2: -2.4012233 | DI2: -2.3528588
A3: 1 | B3: 2.9997621 | C3: 3.1345108 | D3: 2.8874283 | E3: 2.9705987 | F3: 2.7946909 | G3: 3.042679 | H3: 3.1190519 | I3: 2.9485666 | J3: 3.537205 | K3: 2.9970378 | L3: 3.0102508 | M3: 2.8768824 | N3: 2.7467071 | O3: 2.7547907 | P3: 2.6121882 | Q3: 2.7248324 | R3: 2.8057246 | S3: 2.6406755 | T3: 2.666831 | U3: 2.6426764 | V3: 2.5242314 | W3: 2.5028618 | X3: 2.5070969 | Y3: 2.3425576 | Z3: 2.39667 | AA3: 2.3970913 | AB3: 2.3404795 | AC3: 2.4844794 | AD3: 2.3995034 | AE3: 2.2838402 | AF3: 2.1898342 | AG3: 2.3202471 | AH3: 2.2411794 | AI3: 2.2810058 | AJ3: 2.0181179 | AK3: 2.1293802 | AL3: 2.1869626 | AM3: 1.7564835 | AN3: 1.5039503 | AO3: 1.5073743 | AP3: 1.2460486 | AQ3: 1.2258712 | AR3: 1.1328051 | AS3: 0.90811931 | AT3: 0.69145831 | AU3: 0.54613136 | AV3: 0.47309539 | AW3: 0.5348054 | AX3: 0.50693925 | AY3: 0.36666593 | AZ3: 0.29069691 | BA3: 0.12517324 | BB3: 0.12107991 | BC3: 0.00093559645 | BD3: -0.13458006 | BE3: -0.2312683 | BF3: -0.31140825 | BG3: -0.42132095 | BH3: -0.45285725 | BI3: -0.49752969 | BJ3: -0.59111547 | BK3: -0.77009812 | BL3: -0.84842009 | BM3: -0.98825413 | BN3: -1.1135278 | BO3: -1.2195151 | BP3: -1.2535248 | BQ3: -1.3022609 | BR3: -1.3217457 | BS3: -1.3740142 | BT3: -1.3475385 | BU3: -1.4632453 | BV3: -1.5745494 | BW3: -1.5040673 | BX3: -1.8199202 | BY3: -1.7734002 | BZ3: -1.8667124 | CA3: -1.6947571 | CB3: -1.8567818 | CC3: -2.0335851 | CD3: -2.010274 | CE3: -1.8767426 | CF3: -1.8747285 | CG3: -1.9053744 | CH3: -2.0696034 | CI3: -1.9785253 | CJ3: -2.0312293 | CK3: -2.0430638 | CL3: -2.3963432 | CM3: -2.3499772 | CN3: -2.3532187 | CO3: -2.3929591 | CP3: -2.3963432 | CQ3: -2.5618576 | CR3: -2.5303589 | CS3: -2.7220263 | CT3: -2.6152584 | CU3: -2.6716725 | CV3: -2.8001148 | CW3: -2.6495965 | CX3: -2.7220263 | CY3: -2.810319 | CZ3: -2.7034212 | DA3: -2.7750508 | DB3: -3.0398934 | DC3: -2.8154604 | DD3: -2.941655 | DE3: -2.7800136 | DF3: -2.7409843 | DG3: -3.0019141 | DH3: -3.0928859 | DI3: -2.977373
A4: 2 | B4: 2.9362803 | C4: 2.9183226 | D4: 2.7967702 | E4: 2.811221 | F4: 2.6442693 | G4: 2.8408243 | H4: 2.9929728 | I4: 2.7929525 | J4: 3.5996749 | K4: 2.9305968 | L4: 2.8927245 | M4: 2.6966627 | N4: 2.6211477 | O4: 2.5273125 | P4: 2.3636632 | Q4: 2.4924902 | R4: 2.5462883 | S4: 2.3695218 | T4: 2.3607799 | U4: 2.3217854 | V4: 2.1739461 | W4: 2.0988104 | X4: 2.0864051 | Y4: 2.0159879 | Z4: 1.9570516 | AA4: 1.9395159 | AB4: 1.9331198 | AC4: 1.9884087 | AD4: 2.2107652 | AE4: 1.7840923 | AF4: 1.6751471 | AG4: 1.8121233 | AH4: 1.7836726 | AI4: 1.8752647 | AJ4: 1.6830698 | AK4: 1.6858511 | AL4: 1.8108985 | AM4: 1.4554775 | AN4: 1.2084833 | AO4: 1.1433602 | AP4: 0.86037869 | AQ4: 0.77780085 | AR4: 0.75487138 | AS4: 0.64086132 | AT4: 0.44040997 | AU4: 0.39222276 | AV4: 0.32593869 | AW4: 0.33759279 | AX4: 0.30267653 | AY4: 0.24521947 | AZ4: 0.13310217 | BA4: 0.024029044 | BB4: 0.078609613 | BC4: -0.061210068 | BD4: -0.17501696 | BE4: -0.21913057 | BF4: -0.36811061 | BG4: -0.38632605 | BH4: -0.42665031 | BI4: -0.4095721 | BJ4: -0.50733118 | BK4: -0.5304172 | BL4: -0.67892214 | BM4: -0.7610195 | BN4: -0.96332552 | BO4: -0.96989369 | BP4: -1.0487016 | BQ4: -1.1440118 | BR4: -1.1518858 | BS4: -1.1984058 | BT4: -1.0813132 | BU4: -1.3076847 | BV4: -1.3263333 | BW4: -1.2278197 | BX4: -1.4277799 | BY4: -1.4757891 | BZ4: -1.5945973 | CA4: -1.6354193 | CB4: -1.5553766 | CC4: -1.5884623 | CD4: -1.7436329 | CE4: -1.6195207 | CF4: -1.540692 | CG4: -1.3310503 | CH4: -1.5063047 | CI4: -1.6038709 | CJ4: -1.8609696 | CK4: -1.6948427 | CL4: -2.0313149 | CM4: -2.2604287 | CN4: -2.1419805 | CO4: -1.9802598 | CP4: -2.0360882 | CQ4: -2.3349974 | CR4: -2.3158274 | CS4: -2.4155778 | CT4: -2.4956206 | CU4: -2.3677872 | CV4: -2.2193672 | CW4: -2.4657676 | CX4: -2.5186101 | CY4: -2.5581409 | CZ4: -2.4584416 | DA4: -2.3611426 | DB4: -2.4956206 | DC4: -2.599299 | DD4: -2.9839733 | DE4: -2.4584416 | DF4: -2.5032252 | DG4: -2.7055936 | DH4: -2.6962912 | DI4: -2.5662381
A5: 3 | B5: 2.7169012 | C5: 2.7336184 | D5: 2.5878902 | E5: 2.655507 | F5: 2.4506364 | G5: 2.6266598 | H5: 2.7886111 | I5: 2.6365654 | J5: 3.5475061 | K5: 2.7426419 | L5: 2.699468 | M5: 2.4370112 | N5: 2.4460357 | O5: 2.3520762 | P5: 2.3256157 | Q5: 2.2881547 | R5: 2.2640321 | S5: 2.1498905 | T5: 2.1192792 | U5: 2.0644524 | V5: 1.9573826 | W5: 1.9186698 | X5: 1.8544096 | Y5: 1.8598538 | Z5: 1.7773911 | AA5: 1.7482667 | AB5: 1.7195845 | AC5: 1.7593867 | AD5: 1.4085624 | AE5: 1.5598563 | AF5: 1.5140799 | AG5: 1.5980751 | AH5: 1.5364406 | AI5: 1.664503 | AJ5: 1.5320876 | AK5: 1.4760134 | AL5: 1.5241242 | AM5: 1.2590379 | AN5: 1.0113645 | AO5: 0.99011226 | AP5: 0.71294411 | AQ5: 0.64260079 | AR5: 0.59718332 | AS5: 0.49238381 | AT5: 0.4136489 | AU5: 0.33935421 | AV5: 0.261216 | AW5: 0.37467088 | AX5: 0.24410938 | AY5: 0.24626378 | AZ5: 0.12839107 | BA5: 0.059052241 | BB5: 0.0093966501 | BC5: -0.022938731 | BD5: -0.15312228 | BE5: -0.18573386 | BF5: -0.34598044 | BG5: -0.35379297 | BH5: -0.30531409 | BI5: -0.41025959 | BJ5: -0.43405357 | BK5: -0.52441849 | BL5: -0.60847441 | BM5: -0.58185054 | BN5: -0.79722468 | BO5: -0.81365216 | BP5: -0.89111021 | BQ5: -0.91832278 | BR5: -0.92524322 | BS5: -1.0587746 | BT5: -0.92524322 | BU5: -1.0855859 | BV5: -1.2006552 | BW5: -1.0965149 | BX5: -1.2037086 | BY5: -1.2538759 | BZ5: -1.4883373 | CA5: -1.4101725 | CB5: -1.4026818 | CC5: -1.5775684 | CD5: -1.5555895 | CE5: -1.4602793 | CF5: -1.5088719 | CG5: -1.0965149 | CH5: -1.2932252 | CI5: -1.4602793 | CJ5: -1.6706588 | CK5: -1.3482219 | CL5: -1.6657926 | CM5: -1.9310738 | CN5: -2.0591949 | CO5: -1.8877233 | CP5: -1.8175191 | CQ5: -1.9964565 | CR5: -2.1733872 | CS5: -1.976389 | CT5: -2.266281 | CU5: -2.2229842 | CV5: -1.9502437 | CW5: -2.5050324 | CX5: -2.1338564 | CY5: -2.2841386 | CZ5: -2.5510176 | DA5: -2.3884986 | DB5: -2.2061771 | DC5: -2.398549 | DD5: -2.4938591 | DE5: -2.4397919 | DF5: -2.5393215 | DG5: -2.3785483 | DH5: -2.7170027 | DI5: -2.4718802
A6: 4 | B6: 2.5842562 | C6: 2.5869266 | D6: 2.4693325 | E6: 2.4640189 | F6: 2.3654263 | G6: 2.4739215 | H6: 2.6648815 | I6: 2.5332396 | J6: 3.5202289 | K6: 2.711551 | L6: 2.5845235 | M6: 2.3005771 | N6: 2.2308484 | O6: 2.2437111 | P6: 2.2194883 | Q6: 2.2394419 | R6: 2.1429482 | S6: 1.9821234 | T6: 1.981635 | U6: 1.9289781 | V6: 1.8478477 | W6: 1.7726795 | X6: 1.7241602 | Y6: 1.6892194 | Z6: 1.6484792 | AA6: 1.659102 | AB6: 1.5413751 | AC6: 1.6427825 | AD6: 1.2665921 | AE6: 1.4578066 | AF6: 1.3977489 | AG6: 1.513421 | AH6: 1.5108168 | AI6: 1.5702904 | AJ6: 1.5058502 | AK6: 1.3848189 | AL6: 1.4102255 | AM6: 1.1298217 | AN6: 0.93582926 | AO6: 0.91048769 | AP6: 0.63852427 | AQ6: 0.60231835 | AR6: 0.58667266 | AS6: 0.50311963 | AT6: 0.36385757 | AU6: 0.35644097 | AV6: 0.2537421 | AW6: 0.32961623 | AX6: 0.21257633 | AY6: 0.13102022 | AZ6: 0.13309061 | BA6: -0.0029553876 | BB6: -0.0029553876 | BC6: 0.060175152 | BD6: -0.04902414 | BE6: -0.18432953 | BF6: -0.24735404 | BG6: -0.28905893 | BH6: -0.26721719 | BI6: -0.33753368 | BJ6: -0.40074858 | BK6: -0.39371867 | BL6: -0.4476886 | BM6: -0.53251786 | BN6: -0.72008453 | BO6: -0.63631465 | BP6: -0.74465579 | BQ6: -0.8889054 | BR6: -0.87463983 | BS6: -0.97278689 | BT6: -0.91510777 | BU6: -1.1170904 | BV6: -1.1279798 | BW6: -1.0575281 | BX6: -1.0992008 | BY6: -1.1353058 | BZ6: -1.3798157 | CA6: -1.1881483 | CB6: -1.3845216 | CC6: -1.4229879 | CD6: -1.3474803 | CE6: -1.4279019 | CF6: -1.5153612 | CG6: -1.3161579 | CH6: -1.2563109 | CI6: -1.6412415 | CJ6: -1.3520362 | CK6: -1.4579042 | CL6: -1.8138542 | CM6: -1.8432681 | CN6: -1.8138542 | CO6: -1.6473577 | CP6: -1.7371616 | CQ6: -1.8432681 | CR6: -1.9619844 | CS6: -1.9789339 | CT6: -1.7438956 | CU6: -2.1561404 | CV6: -2.2751998 | CW6: -2.068279 | CX6: -2.0871475 | CY6: -2.1978131 | CZ6: -2.2193193 | DA6: -2.3222673 | DB6: -2.2302484 | DC6: -2.2524715 | DD6: -2.630234 | DE6: -2.2984566 | DF6: -2.2751998 | DG6: -2.3973025 | DH6: -2.4236198 | DI6: -2.5667206
A7: 5 | B7: 2.4092796 | C7: 2.4162954 | D7: 2.2782409 | E7: 2.3750633 | F7: 2.186462 | G7: 2.3330432 | H7: 2.5224453 | I7: 2.4403436 | J7: 3.4117122 | K7: 2.57052 | L7: 2.4676469 | M7: 2.1268856 | N7: 2.0679455 | O7: 2.0152225 | P7: 2.1023789 | Q7: 2.1251549 | R7: 2.0514865 | S7: 1.8829057 | T7: 1.8487834 | U7: 1.8041863 | V7: 1.7182163 | W7: 1.6548394 | X7: 1.6473258 | Y7: 1.6329776 | Z7: 1.5698171 | AA7: 1.5995547 | AB7: 1.5196829 | AC7: 1.5142732 | AD7: 1.4755629 | AE7: 1.3832002 | AF7: 1.2890534 | AG7: 1.4015824 | AH7: 1.4554617 | AI7: 1.5995547 | AJ7: 1.5069072 | AK7: 1.3893653 | AL7: 1.3111887 | AM7: 1.0912652 | AN7: 0.91428732 | AO7: 0.8306529 | AP7: 0.60545287 | AQ7: 0.53578111 | AR7: 0.53832456 | AS7: 0.45262093 | AT7: 0.28966778 | AU7: 0.34664522 | AV7: 0.23270096 | AW7: 0.26437782 | AX7: 0.26660251 | AY7: 0.23843163 | AZ7: 0.076248782 | BA7: 0.10408358 | BB7: -0.0020034147 | BC7: 0.003793703 | BD7: -0.13387506 | BE7: -0.15059785 | BF7: -0.15566972 | BG7: -0.27049104 | BH7: -0.23317328 | BI7: -0.23134345 | BJ7: -0.29356899 | BK7: -0.34342976 | BL7: -0.45585906 | BM7: -0.35784814 | BN7: -0.60620311 | BO7: -0.63863838 | BP7: -0.65525927 | BQ7: -0.77689048 | BR7: -0.85561964 | BS7: -0.81548048 | BT7: -0.73367388 | BU7: -0.92632046 | BV7: -0.95606243 | BW7: -1.0804711 | BX7: -1.1982542 | BY7: -1.2275246 | BZ7: -1.2835188 | CA7: -1.2127823 | CB7: -1.1467205 | CC7: -1.3317856 | CD7: -1.2424874 | CE7: -1.0719604 | CF7: -1.2627927 | CG7: -1.1698162 | CH7: -1.2374749 | CI7: -1.1286205 | CJ7: -1.2940452 | CK7: -1.3710063 | CL7: -1.8353119 | CM7: -1.5941498 | CN7: -1.6995103 | CO7: -1.7155107 | CP7: -1.6995103 | CQ7: -1.9206717 | CR7: -2.0359826 | CS7: -1.8444444 | CT7: -2.0471559 | CU7: -2.1663444 | CV7: -2.1663444 | CW7: -2.1413431 | CX7: -2.1049755 | CY7: -1.9508248 | CZ7: -2.081445 | DA7: -2.361405 | DB7: -2.2731124 | DC7: -2.3926575 | DD7: -2.3461375 | DE7: -2.2050589 | DF7: -2.0031928 | DG7: -2.7516026 | DH7: -2.361405 | DI7: -2.3461375
A8: 6 | B8: 2.2665687 | C8: 2.3041188 | D8: 2.1374998 | E8: 2.1513499 | F8: 2.0996652 | G8: 2.155986 | H8: 2.3493472 | I8: 2.2769503 | J8: 3.351449 | K8: 2.4520051 | L8: 2.3171163 | M8: 2.0587127 | N8: 1.8984942 | O8: 1.8433892 | P8: 1.8388265 | Q8: 1.9984067 | R8: 1.9326111 | S8: 1.8484347 | T8: 1.7208529 | U8: 1.6977171 | V8: 1.606815 | W8: 1.5402451 | X8: 1.5409298 | Y8: 1.4932684 | Z8: 1.4488656 | AA8: 1.451863 | AB8: 1.3765168 | AC8: 1.4199332 | AD8: 1.4071051 | AE8: 1.3395364 | AF8: 1.2186615 | AG8: 1.2950275 | AH8: 1.3622976 | AI8: 1.6029627 | AJ8: 1.5152785 | AK8: 1.3757097 | AL8: 1.2125018 | AM8: 1.0480799 | AN8: 0.82912926 | AO8: 0.76654142 | AP8: 0.52409623 | AQ8: 0.46163691 | AR8: 0.42992069 | AS8: 0.41736823 | AT8: 0.25794049 | AU8: 0.28593989 | AV8: 0.24551797 | AW8: 0.20469598 | AX8: 0.23040433 | AY8: 0.11341413 | AZ8: 0.097597841 | BA8: 0.071164584 | BB8: 0.0239357 | BC8: 0.0050375002 | BD8: -0.08820804 | BE8: -0.16999747 | BF8: -0.23858458 | BG8: -0.24468837 | BH8: -0.29490812 | BI8: -0.32320163 | BJ8: -0.31879634 | BK8: -0.3387748 | BL8: -0.34101947 | BM8: -0.39408844 | BN8: -0.5391964 | BO8: -0.42782658 | BP8: -0.59265498 | BQ8: -0.56979684 | BR8: -0.6219826 | BS8: -0.88613417 | BT8: -0.60428302 | BU8: -0.88226569 | BV8: -0.79364686 | BW8: -0.94192553 | BX8: -1.0274477 | BY8: -1.0731177 | BZ8: -1.0919862 | CA8: -1.1160838 | CB8: -1.2800385 | CC8: -1.2915993 | CD8: -1.4486612 | CE8: -1.1712356 | CF8: -1.3514974 | CG8: -0.95845483 | CH8: -1.1712356 | CI8: -1.0364164 | CJ8: -1.4086558 | CK8: -1.1815984 | CL8: -1.5046198 | CM8: -1.5046198 | CN8: -1.5191128 | CO8: -1.6941616 | CP8: -1.4486612 | CQ8: -1.7662649 | CR8: -1.8852169 | CS8: -1.8852169 | CT8: -1.7756547 | CU8: -1.8439739 | CV8: -1.9847465 | CW8: -2.0446446 | CX8: -2.0202531 | CY8: -2.0823849 | CZ8: -2.2049873 | DA8: -2.3282199 | DB8: -1.9617569 | DC8: -2.3119594 | DD8: -1.9847465 | DE8: -1.9064943 | DF8: -2.3119594 | DG8: -2.2195861 | DH8: -2.1486343 | DI8: -2.3615563
A9: 7 | B9: 2.1219446 | C9: 2.2002629 | D9: 2.0345738 | E9: 2.0268759 | F9: 1.9937319 | G9: 2.1022078 | H9: 2.1904689 | I9: 2.2171749 | J9: 3.2717074 | K9: 2.3668952 | L9: 2.2390931 | M9: 2.0066289 | N9: 1.8211481 | O9: 1.6985328 | P9: 1.7858236 | Q9: 1.8202577 | R9: 1.8175819 | S9: 1.7514345 | T9: 1.717138 | U9: 1.6146262 | V9: 1.5222294 | W9: 1.5246265 | X9: 1.4884657 | Y9: 1.4487981 | Z9: 1.4414531 | AA9: 1.4392824 | AB9: 1.3549934 | AC9: 1.4168688 | AD9: 1.3526266 | AE9: 1.2608646 | AF9: 1.2020241 | AG9: 1.3435811 | AH9: 1.3320369 | AI9: 1.5683493 | AJ9: 1.5733026 | AK9: 1.4457802 | AL9: 1.2477925 | AM9: 1.0357711 | AN9: 0.84259053 | AO9: 0.72815627 | AP9: 0.55464534 | AQ9: 0.49164949 | AR9: 0.39645141 | AS9: 0.45859804 | AT9: 0.27186352 | AU9: 0.28985709 | AV9: 0.30618398 | AW9: 0.31825656 | AX9: 0.24065531 | AY9: 0.069795201 | AZ9: 0.064653801 | BA9: -0.0083973677 | BB9: 0.031462982 | BC9: 0.096778288 | BD9: -0.023295222 | BE9: -0.06936863 | BF9: -0.24972748 | BG9: -0.23570856 | BH9: -0.31788037 | BI9: -0.38023823 | BJ9: -0.21731723 | BK9: -0.27836905 | BL9: -0.3103521 | BM9: -0.41849426 | BN9: -0.38023823 | BO9: -0.59138963 | BP9: -0.5057589 | BQ9: -0.46993417 | BR9: -0.63885617 | BS9: -0.78035573 | BT9: -0.51799146 | BU9: -0.80055844 | BV9: -0.87686663 | BW9: -0.90365395 | BX9: -0.91274492 | BY9: -1.0135496 | BZ9: -1.023702 | CA9: -1.1144308 | CB9: -1.070708 | CC9: -1.2019502 | CD9: -1.1898289 | CE9: -1.2329124 | CF9: -1.1898289 | CG9: -1.0923305 | CH9: -1.0814608 | CI9: -1.1144308 | CJ9: -1.070708 | CK9: -1.2019502 | CL9: -1.4342822 | CM9: -1.6013363 | CN9: -1.6289878 | CO9: -1.7585219 | CP9: -1.4497864 | CQ9: -1.5656182 | CR9: -1.8709998 | CS9: -1.7168492 | CT9: -1.9073675 | CU9: -1.7585219 | CV9: -2.0823089 | CW9: -1.6289878 | CX9: -1.8950974 | CY9: -1.9977516 | CZ9: -2.0533214 | DA9: -1.7800281 | DB9: -2.276465 | DC9: -2.3128326 | DD9: -2.2074721 | DE9: -2.0251505 | DF9: -2.2944835 | DG9: -2.4951542 | DH9: -2.4731753 | DI9: -2.2587654
A10: 8 | B10: 2.0226414 | C10: 2.0226414 | D10: 1.9236611 | E10: 1.9590758 | F10: 1.8354767 | G10: 1.9894445 | H10: 2.1458664 | I10: 2.1261951 | J10: 3.3076815 | K10: 2.3067999 | L10: 2.1988831 | M10: 1.8669853 | N10: 1.7815517 | O10: 1.6644864 | P10: 1.638321 | Q10: 1.6791897 | R10: 1.6896143 | S10: 1.6285266 | T10: 1.6580089 | U10: 1.6285266 | V10: 1.5183425 | W10: 1.4701676 | X10: 1.4627601 | Y10: 1.4277684 | Z10: 1.3424181 | AA10: 1.365217 | AB10: 1.3355813 | AC10: 1.4029193 | AD10: 1.2639464 | AE10: 1.206788 | AF10: 1.2079878 | AG10: 1.2796948 | AH10: 1.3028619 | AI10: 1.646088 | AJ10: 1.6289202 | AK10: 1.4798073 | AL10: 1.2085871 | AM10: 1.043492 | AN10: 0.7565164 | AO10: 0.67819851 | AP10: 0.47571581 | AQ10: 0.45301622 | AR10: 0.41001285 | AS10: 0.33251905 | AT10: 0.25630593 | AU10: 0.22315372 | AV10: 0.21832668 | AW10: 0.27171455 | AX10: 0.21022947 | AY10: 0.18886464 | AZ10: 0.067128624 | BA10: -0.077994757 | BB10: 0.034713965 | BC10: 0.015143869 | BD10: -0.10436991 | BE10: -0.14993588 | BF10: -0.20257962 | BG10: -0.23504189 | BH10: -0.20012563 | BI10: -0.23504189 | BJ10: -0.31423893 | BK10: -0.26859343 | BL10: -0.26597219 | BM10: -0.34209589 | BN10: -0.43684125 | BO10: -0.40325031 | BP10: -0.36206802 | BQ10: -0.53122019 | BR10: -0.57303813 | BS10: -0.5946217 | BT10: -0.55890362 | BU10: -0.88351663 | BV10: -0.7952924 | BW10: -0.86428527 | BX10: -0.8132301 | BY10: -0.85953467 | BZ10: -1.0352431 | CA10: -0.95389743 | CB10: -1.2769189 | CC10: -1.1424886 | CD10: -1.1744402 | CE10: -0.94870261 | CF10: -1.0128958 | CG10: -0.99645704 | CH10: -1.2141805 | CI10: -1.093399 | CJ10: -1.1176426 | CK10: -1.3515804 | CL10: -1.4407082 | CM10: -1.8169436 | CN10: -1.2697504 | CO10: -1.6062226 | CP10: -1.306118 | CQ10: -1.7227564 | CR10: -1.7115831 | CS10: -1.9073277 | CT10: -1.854684 | CU10: -1.5962723 | CV10: -1.9073277 | CW10: -1.9772863 | CX10: -2.1860411 | CY10: -1.7570455 | CZ10: -2.0682581 | DA10: -2.1860411 | DB10: -2.1170482 | DC10: -2.0682581 | DD10: -1.7925522 | DE10: -2.1509498 | DF10: -2.0682581 | DG10: -2.2411009 | DH10: -2.2224088 | DI10: -1.8939047
A11: 9 | B11: 1.9234779 | C11: 1.9625797 | D11: 1.8268376 | E11: 1.8566906 | F11: 1.7456593 | G11: 1.8869614 | H11: 2.0373032 | I11: 2.1039946 | J11: 3.1938808 | K11: 2.2193949 | L11: 2.1221514 | M11: 1.9274884 | N11: 1.7118596 | O11: 1.7386183 | P11: 1.6148674 | Q11: 1.5810529 | R11: 1.5149168 | S11: 1.5492059 | T11: 1.6352805 | U11: 1.5478566 | V11: 1.5032208 | W11: 1.3684112 | X11: 1.407487 | Y11: 1.3996886 | Z11: 1.3608436 | AA11: 1.3389009 | AB11: 1.2520408 | AC11: 1.3592145 | AD11: 1.1766756 | AE11: 1.2219495 | AF11: 1.1915674 | AG11: 1.2263041 | AH11: 1.3215578 | AI11: 1.6697317 | AJ11: 1.67569 | AK11: 1.4880474 | AL11: 1.2508301 | AM11: 1.0715325 | AN11: 0.82641 | AO11: 0.71174709 | AP11: 0.43610714 | AQ11: 0.39989148 | AR11: 0.37548252 | AS11: 0.36378648 | AT11: 0.228573 | AU11: 0.15885836 | AV11: 0.2167185 | AW11: 0.28104405 | AX11: 0.070204681 | AY11: 0.14614248 | AZ11: -0.060232041 | BA11: -0.0098380269 | BB11: 0.0071115314 | BC11: 0.015479781 | BD11: -0.12282489 | BE11: -0.07380691 | BF11: -0.16684178 | BG11: -0.26390349 | BH11: -0.1204354 | BI11: -0.21288571 | BJ11: -0.30610384 | BK11: -0.38375478 | BL11: -0.32936071 | BM11: -0.28618853 | BN11: -0.41210313 | BO11: -0.48155252 | BP11: -0.5785765 | BQ11: -0.47813371 | BR11: -0.55250426 | BS11: -0.58615229 | BT11: -0.39940455 | BU11: -0.62491683 | BV11: -0.74666027 | BW11: -0.80172005 | BX11: -0.91128225 | BY11: -0.88019166 | BZ11: -1.0284076 | CA11: -1.0403125 | CB11: -1.0284076 | CC11: -1.07071 | CD11: -0.95980929 | CE11: -1.2984939 | CF11: -1.161094 | CG11: -0.9379505 | CH11: -0.96534947 | CI11: -1.3876217 | CJ11: -1.1410265 | CK11: -1.3141192 | CL11: -1.1148812 | CM11: -1.5139154 | CN11: -1.3542853 | CO11: -1.4398075 | CP11: -1.346122 | CQ11: -1.6923982 | CR11: -1.7394657 | CS11: -1.5835953 | CT11: -1.7274895 | CU11: -1.9098111 | CV11: -1.9241998 | CW11: -1.6150115 | CX11: -1.9536137 | CY11: -1.703959 | CZ11: -2.0311719 | DA11: -1.8145009 | DB11: -2.0311719 | DC11: -1.9536137 | DD11: -1.827573 | DE11: -1.7888585 | DF11: -2.0311719 | DG11: -2.0474325 | DH11: -2.3516438 | DI11: -2.6029583
A12: 10 | B12: 1.8581022 | C12: 1.955103 | D12: 1.7894719 | E12: 1.8060071 | F12: 1.7491632 | G12: 1.887776 | H12: 1.9709473 | I12: 2.0285087 | J12: 3.236071 | K12: 2.1528658 | L12: 2.0775163 | M12: 1.8431002 | N12: 1.7335706 | O12: 1.617463 | P12: 1.6563029 | Q12: 1.6243271 | R12: 1.5725611 | S12: 1.5098519 | T12: 1.4677508 | U12: 1.5011855 | V12: 1.4148773 | W12: 1.4561841 | X12: 1.3668248 | Y12: 1.325611 | Z12: 1.2868282 | AA12: 1.2916101 | AB12: 1.2686899 | AC12: 1.3233028 | AD12: 1.2874272 | AE12: 1.2237665 | AF12: 1.2135035 | AG12: 1.1867132 | AH12: 1.2868282 | AI12: 1.7185095 | AJ12: 1.6776064 | AK12: 1.5136797 | AL12: 1.2231282 | AM12: 1.04996 | AN12: 0.8413272 | AO12: 0.71697446 | AP12: 0.45714934 | AQ12: 0.42362665 | AR12: 0.35453231 | AS12: 0.34073899 | AT12: 0.26210989 | AU12: 0.15841743 | AV12: 0.19120725 | AW12: 0.31731871 | AX12: 0.06329242 | AY12: 0.073424219 | AZ12: 0.061253683 | BA12: 0.00024633484 | BB12: -0.048652295 | BC12: -0.01505451 | BD12: -0.069366499 | BE12: -0.15426594 | BF12: -0.32801674 | BG12: -0.16188987 | BH12: -0.20090652 | BI12: -0.24704768 | BJ12: -0.32201072 | BK12: -0.34319154 | BL12: -0.3401381 | BM12: -0.25261872 | BN12: -0.54216473 | BO12: -0.4983621 | BP12: -0.4529791 | BQ12: -0.56099768 | BR12: -0.51275084 | BS12: -0.58407562 | BT12: -0.59581744 | BU12: -0.79561363 | BV12: -0.87565634 | BW12: -0.75325435 | BX12: -0.84994798 | BY12: -0.76717569 | BZ12: -0.83483434 | CA12: -0.88087828 | CB12: -1.1633384 | CC12: -1.1427191 | CD12: -1.1027138 | CE12: -1.1843918 | CF12: -0.97986011 | CG12: -1.0091877 | CH12: -1.0455554 | CI12: -1.0705567 | CJ12: -1.2131708 | CK12: -1.3291307 | CL12: -1.2353119 | CM12: -1.4984227 | CN12: -1.6113631 | CO12: -1.4887608 | CP12: -1.3291307 | CQ12: -1.6788044 | CR12: -1.8156636 | CS12: -1.6558149 | CT12: -1.990017 | CU12: -1.4984227 | CV12: -1.7264325 | CW12: -1.8290866 | CX12: -1.8990452 | CY12: -1.8156636 | CZ12: -1.8156636 | DA12: -1.9284591 | DB12: -2.3264892 | DC12: -2.181908 | DD12: -1.5688035 | DE12: -1.6222922 | DF12: -1.990017 | DG12: -1.8290866 | DH12: -2.0222778 | DI12: -1.8290866
A13: 11 | B13: 1.7836093 | C13: 1.8563244 | D13: 1.7129654 | E13: 1.7321451 | F13: 1.6842853 | G13: 1.8187131 | H13: 1.8693267 | I13: 1.9025545 | J13: 3.069084 | K13: 2.0310669 | L13: 1.9408999 | M13: 1.7642974 | N13: 1.6111273 | O13: 1.5815342 | P13: 1.5855016 | Q13: 1.5601048 | R13: 1.5331194 | S13: 1.4094079 | T13: 1.3665288 | U13: 1.4255415 | V13: 1.331418 | W13: 1.3471752 | X13: 1.4004487 | Y13: 1.2938522 | Z13: 1.2962051 | AA13: 1.2688061 | AB13: 1.1758482 | AC13: 1.2784216 | AD13: 1.2418767 | AE13: 1.1678642 | AF13: 1.1448902 | AG13: 1.2306476 | AH13: 1.2742262 | AI13: 1.7121905 | AJ13: 1.7051893 | AK13: 1.5063384 | AL13: 1.1665273 | AM13: 1.0313701 | AN13: 0.79493027 | AO13: 0.67338167 | AP13: 0.48996422 | AQ13: 0.41908988 | AR13: 0.29918595 | AS13: 0.22311624 | AT13: 0.22311624 | AU13: 0.1683806 | AV13: 0.1104746 | AW13: 0.27826806 | AX13: 0.0072485567 | AY13: 0.073251889 | AZ13: -0.027462086 | BA13: 0.051051179 | BB13: -0.061135301 | BC13: 0.042854412 | BD13: -0.10787278 | BE13: -0.20581801 | BF13: -0.17209237 | BG13: -0.15439279 | BH13: -0.26842348 | BI13: -0.31440859 | BJ13: -0.30854347 | BK13: -0.34123584 | BL13: -0.28828229 | BM13: -0.32327128 | BN13: -0.43292719 | BO13: -0.4873624 | BP13: -0.39078157 | BQ13: -0.41650646 | BR13: -0.53388242 | BS13: -0.43292719 | BT13: -0.41325443 | BU13: -0.79149608 | BV13: -0.7680758 | BW13: -0.74067683 | BX13: -0.80581613 | BY13: -0.87035465 | BZ13: -0.80581613 | CA13: -1.0681804 | CB13: -1.0016907 | CC13: -1.0871084 | CD13: -1.07445 | CE13: -1.0134555 | CF13: -1.0193902 | CG13: -0.85004939 | CH13: -1.2161005 | CI13: -1.0807592 | CJ13: -1.0193902 | CK13: -0.97287022 | CL13: -1.1394079 | CM13: -1.3150405 | CN13: -1.1394079 | CO13: -1.2758198 | CP13: -1.5686432 | CQ13: -1.5183814 | CR13: -1.433824 | CS13: -1.9844711 | CT13: -1.7866454 | CU13: -1.6890069 | CV13: -1.736635 | CW13: -1.4705254 | CX13: -1.5583867 | CY13: -1.8392891 | CZ13: -2.1003029 | DA13: -1.894859 | DB13: -1.8392891 | DC13: -1.8528948 | DD13: -2.0658168 | DE13: -1.6547178 | DF13: -1.8666881 | DG13: -1.9386616 | DH13: -1.9386616 | DI13: -2.1921105
... A112: 110 | B112: 0.17936387 | C112: 1.13572 | D112: -0.34723569 | E112: 0.52442548 | F112: 0.11843815 | G112: -0.19462941 | H112: 1.1261944 | I112: 1.4876965 | J112: -0.53458623 | K112: 1.4876965 | L112: -0.68773336 | M112: 0.43454642 | N112: 0.57713635 | O112: -0.010792089 | P112: 1.4876965 | Q112: 0.47753954 | R112: 0.012216719 | S112: 1.4876965 | T112: -1.584226 | U112: 1.4876965 | V112: 0.57140572 | W112: -0.21705172 | X112: 0.38908417 | Y112: -0.52720657 | Z112: 1.4876965 | AA112: 0.10140209 | AB112: 0.79454927 | AC112: -1.1573789 | AD112: 1.4876965 | AE112: -0.81488864 | AF112: -0.23277358 | AG112: -0.12174146 | AH112: 0.79454927 | AI112: 1.4876965 | AJ112: 0.47964353 | AK112: 1.1462532 | AL112: 1.4876965 | AM112: 0.26912483 | AN112: 0.50319736 | AO112: -0.23403428 | AP112: -1.1697628 | AQ112: -0.011926379 | AR112: 1.0956544 | AS112: -0.29063951 | AT112: -0.86177237 | AU112: 0.021359108 | AV112: 0.10140209 | AW112: 0.79454927 | AX112: -0.016381192 | AY112: -0.12174146 | AZ112: 1.4876965 | BA112: 0.10140209 | BB112: -0.45821353 | BC112: -0.59174509 | BD112: 1.4876965 | BE112: 0.79454927 | BF112: -1.1513619 | BG112: -0.91019798 | BH112: -0.12174146 | BI112: -0.12174146 | BJ112: 0.79454927 | BK112: -0.45821353 | BL112: 0.10140209 | BM112: 1.4876965 | BN112: 0.57140572 | BO112: -1.0772539 | BP112: 1.0822313 | BQ112: -1.1513619 | BR112: -0.12174146 | BS112: 0.79454927 | BT112: 0.45926813 | BU112: 0.79454927 | BV112: -0.21705172 | BW112: -0.12174146 | BX112: -0.30406301 | BY112: -0.12174146 | BZ112: 0.79454927 | CA112: -1.3257143 | CB112: -1.0772539 | CC112: -0.45821353 | CD112: -1.603347 | CE112: 0.23493365 | CF112: -1.2848923 | CG112: -0.12174146 | CH112: -1.3455174 | CI112: -0.18627998 | CJ112: -0.78098653 | CK112: 0.10140209 | CL112: 0.38908417 | CM112: -0.35813068 | CN112: -1.253143 | CO112: -1.0512779 | CP112: -0.3912595 | CQ112: -0.45367966 | CR112: -0.89485399 | CS112: 0.06382829 | CT112: -0.74714432 | CU112: -0.17403262 | CV112: -0.19452723 | CW112: -0.48733462 | CX112: -1.1551865 | CY112: -0.057226375 | CZ112: -0.23213313 | DA112: -0.33485011 | DB112: -0.54249662 | DC112: -0.89420966 | DD112: -0.32507319 | DE112: -0.58327043 | DF112: -0.86406313 | DG112: -0.24534704 | DH112: -0.31821468 | DI112: -0.77174454

Sheet U
B1: 0 | C1: 1 | D1: 2 | E1: 3 | F1: 4 | G1: 5 | H1: 6 | I1: 7 | J1: 8 | K1: 9 | L1: 10 | M1: 11 | N1: 12 | O1: 13 | P1: 14 | Q1: 15 | R1: 16 | S1: 17 | T1: 18 | U1: 19 | V1: 20 | W1: 21 | X1: 22 | Y1: 23 | Z1: 24 | AA1: 25 | AB1: 26 | AC1: 27 | AD1: 28 | AE1: 29 | AF1: 30 | AG1: 31 | AH1: 32 | AI1: 33 | AJ1: 34 | AK1: 35 | AL1: 36 | AM1: 37 | AN1: 38 | AO1: 39 | AP1: 40 | AQ1: 41 | AR1: 42 | AS1: 43 | AT1: 44 | AU1: 45 | AV1: 46 | AW1: 47 | AX1: 48 | AY1: 49 | AZ1: 50 | BA1: 51 | BB1: 52 | BC1: 53 | BD1: 54 | BE1: 55 | BF1: 56 | BG1: 57 | BH1: 58 | BI1: 59 | BJ1: 60 | BK1: 61 | BL1: 62 | BM1: 63 | BN1: 64 | BO1: 65 | BP1: 66 | BQ1: 67 | BR1: 68 | BS1: 69 | BT1: 70 | BU1: 71 | BV1: 72 | BW1: 73 | BX1: 74 | BY1: 75 | BZ1: 76 | CA1: 77 | CB1: 78 | CC1: 79 | CD1: 80 | CE1: 81 | CF1: 82 | CG1: 83 | CH1: 84 | CI1: 85 | CJ1: 86 | CK1: 87 | CL1: 88 | CM1: 89 | CN1: 90 | CO1: 91 | CP1: 92 | CQ1: 93 | CR1: 94 | CS1: 95 | CT1: 96 | CU1: 97 | CV1: 98 | CW1: 99 | CX1: 100 | CY1: 101 | CZ1: 102 | DA1: 103 | DB1: 104 | DC1: 105 | DD1: 106 | DE1: 107 | DF1: 108 | DG1: 109 | DH1: 110
A2: 0 | B2: 0.15941769 | C2: 0.010788741 | D2: -0.24552786 | E2: 0.029067524 | F2: -0.061577267 | G2: 0.2307188 | H2: -0.033534184 | I2: -0.028832479 | J2: 0.068201172 | K2: -0.029794106 | L2: 0.053105059 | M2: -0.06215183 | N2: 0.038249457 | O2: -0.00010418106 | P2: 0.14323941 | Q2: -0.3193585 | R2: 0.20515379 | S2: -0.088019462 | T2: 0.1391661 | U2: -0.0653028 | V2: 0.21071663 | W2: 0.076253089 | X2: -0.06944423 | Y2: -0.092430427 | Z2: 0.3280569 | AA2: 0.10083231 | AB2: -0.044214942 | AC2: 0.27646136 | AD2: -0.20017639 | AE2: 0.067732632 | AF2: -0.015628629 | AG2: 0.26514 | AH2: -0.022616235 | AI2: 0.15648473 | AJ2: -0.011068821 | AK2: 0.042504113 | AL2: -0.249299 | AM2: 0.16963812 | AN2: -0.050153783 | AO2: 0.019062173 | AP2: -0.021498563 | AQ2: -0.063892595 | AR2: 0.12261991 | AS2: -0.029253905 | AT2: -0.030375259 | AU2: 0.086885791 | AV2: -0.091024477 | AW2: -0.017526945 | AX2: -0.085754998 | AY2: 0.098917998 | AZ2: 0.059128632 | BA2: -0.044687608 | BB2: -0.012965753 | BC2: -0.060428972 | BD2: 0.096862592 | BE2: 0.023310622 | BF2: 0.069525813 | BG2: -0.012777874 | BH2: -0.0027898384 | BI2: -0.1336946 | BJ2: 0.094341334 | BK2: 0.011271819 | BL2: 0.0065456498 | BM2: 0.025861864 | BN2: 0.0047410186 | BO2: 0.028143905 | BP2: 0.070794931 | BQ2: -0.076927699 | BR2: 0.030725197 | BS2: 0.015285357 | BT2: 0.00837355 | BU2: 0.008555475 | BV2: 0.031610361 | BW2: 0.0086570013 | BX2: 0.023951198 | BY2: -0.043349145 | BZ2: -0.011429444 | CA2: -0.0009929361 | CB2: -0.021233738 | CC2: -0.043786561 | CD2: -0.043389457 | CE2: 0.016812795 | CF2: 0.0041242032 | CG2: 0.0029809227 | CH2: 0.018379844 | CI2: 0.031228192 | CJ2: 0.026957127 | CK2: 0.033485012 | CL2: 0.02657338 | CM2: -0.011041333 | CN2: -0.0088625467 | CO2: -0.010718459 | CP2: -0.043953253 | CQ2: -0.043644383 | CR2: -0.016290502 | CS2: -0.0011241678 | CT2: -0.011169151 | CU2: -0.041165676 | CV2: 0.015131329 | CW2: 0.043622061 | CX2: 0.02013771 | CY2: 0.04283801 | CZ2: 0.052693671 | DA2: 0.00017485573 | DB2: 0.015085358 | DC2: 0.0083826396 | DD2: 0.036183213 | DE2: 0.017544909 | DF2: 0.017879585 | DG2: 0.016432842 | DH2: 0.038370967 | DI2: {=SUMPRODUCT(POWER(B2:DH2,2))} -> 1
A3: 1 | B3: 0.24274326 | C3: 0.017742703 | D3: -0.11647323 | E3: 0.38635068 | F3: 0.073911106 | G3: 0.35491041 | H3: -0.058016873 | I3: 0.12662187 | J3: -0.013052923 | K3: 0.053217083 | L3: -0.061499801 | M3: -0.11870205 | N3: 0.048332045 | O3: -0.058288804 | P3: 0.12120872 | Q3: -0.071593783 | R3: 0.3405179 | S3: -0.16982966 | T3: -0.16786898 | U3: -0.0091104974 | V3: -0.084790771 | W3: 0.12409439 | X3: -0.07493106 | Y3: -0.081565564 | Z3: -0.092740086 | AA3: -0.097057659 | AB3: -0.17535039 | AC3: -0.093875437 | AD3: 0.17762426 | AE3: 0.058576683 | AF3: 0.18453963 | AG3: -0.051934348 | AH3: 0.058386571 | AI3: -0.17081035 | AJ3: -0.1243491 | AK3: -0.038305801 | AL3: 0.15373693 | AM3: -0.12832284 | AN3: 0.047728685 | AO3: 0.073925353 | AP3: 0.032231092 | AQ3: -0.1034337 | AR3: -0.17765599 | AS3: -0.077955696 | AT3: 0.099052932 | AU3: -0.016953657 | AV3: 0.019645387 | AW3: 0.056302768 | AX3: -0.014399543 | AY3: -0.045620837 | AZ3: 0.0034363939 | BA3: 0.045079379 | BB3: 0.041544901 | BC3: 0.028795818 | BD3: 0.0070405444 | BE3: -0.060176289 | BF3: -0.040879784 | BG3: 0.024725575 | BH3: 0.031484382 | BI3: 0.042778906 | BJ3: -0.038773833 | BK3: 0.0044520573 | BL3: -0.1091928 | BM3: -0.00043689152 | BN3: 0.071276316 | BO3: -0.058467378 | BP3: -0.049740439 | BQ3: 0.091485938 | BR3: -0.084119964 | BS3: -0.029864706 | BT3: 0.01161636 | BU3: -0.049375735 | BV3: -0.035340431 | BW3: 0.01508275 | BX3: -0.028057497 | BY3: 0.020872244 | BZ3: -0.045864442 | CA3: -0.033345008 | CB3: 0.00061448366 | CC3: -0.0088692716 | CD3: -0.0037026493 | CE3: 0.011293703 | CF3: 0.052108404 | CG3: 0.00097091167 | CH3: -0.0046511243 | CI3: -0.049319623 | CJ3: -0.032390303 | CK3: -0.059544845 | CL3: 0.037124855 | CM3: -0.013214512 | CN3: 0.00043157535 | CO3: 0.0047114097 | CP3: 0.021234885 | CQ3: 0.028850766 | CR3: 0.026136772 | CS3: 0.018985538 | CT3: 0.014478835 | CU3: 0.014160838 | CV3: 0.026646293 | CW3: -0.0073913091 | CX3: -0.0060672509 | CY3: -0.011771101 | CZ3: -0.0064161507 | DA3: -0.014223025 | DB3: -0.013342684 | DC3: 0.0092795092 | DD3: -0.033898024 | DE3: -0.020898926 | DF3: 0.019381039 | DG3: -0.00080664513 | DH3: -0.021090063 | DI3: {=SUMPRODUCT(POWER(B3:DH3,2))} -> 1
A4: 2 | B4: 0.21618545 | C4: 0.023070982 | D4: -0.074901649 | E4: 0.29906697 | F4: 0.13094451 | G4: 0.15244394 | H4: 0.0049963641 | I4: 0.046893971 | J4: -0.036848046 | K4: -0.022965057 | L4: 0.018690477 | M4: -0.034154003 | N4: -0.09023012 | O4: -0.11718028 | P4: -0.068158209 | Q4: 0.19190007 | R4: -0.039650316 | S4: -0.14893724 | T4: -0.020867369 | U4: 0.14971295 | V4: -0.084919013 | W4: -0.097937939 | X4: -0.081274373 | Y4: -0.1156473 | Z4: -0.10940264 | AA4: -0.1182917 | AB4: 0.27568013 | AC4: -0.011272064 | AD4: -0.019584602 | AE4: -0.086258373 | AF4: -0.43345913 | AG4: 0.042711375 | AH4: 0.12446303 | AI4: 0.11077097 | AJ4: 0.058863932 | AK4: 0.086835261 | AL4: 0.11283756 | AM4: 0.038148465 | AN4: -0.255582 | AO4: -0.16167207 | AP4: -0.14213907 | AQ4: 0.17672971 | AR4: 0.1748468 | AS4: 0.029573311 | AT4: 0.029412622 | AU4: -0.071999623 | AV4: -0.0080508015 | AW4: -0.07592045 | AX4: -0.0088906674 | AY4: 0.071155416 | AZ4: -0.0048469486 | BA4: -0.015762355 | BB4: 0.048137092 | BC4: 0.033814495 | BD4: 0.025429749 | BE4: 0.010987177 | BF4: -0.0019399835 | BG4: 0.062678035 | BH4: -0.059377863 | BI4: -0.021719045 | BJ4: 0.094475201 | BK4: -0.058347099 | BL4: 0.0935196 | BM4: 0.018425432 | BN4: -0.044046801 | BO4: 0.0018133998 | BP4: -0.022448132 | BQ4: -0.10094362 | BR4: 0.040085918 | BS4: 0.00076522868 | BT4: 0.062296735 | BU4: -0.028931509 | BV4: 0.07769746 | BW4: -0.044858585 | BX4: 0.069113265 | BY4: 0.052873947 | BZ4: 0.0223538 | CA4: -0.0036180897 | CB4: 0.03662361 | CC4: -0.023129953 | CD4: -0.0021649044 | CE4: -0.0096519868 | CF4: 0.034075249 | CG4: -0.028449003 | CH4: 0.046889956 | CI4: 0.041972287 | CJ4: 0.038752882 | CK4: 0.0026130133 | CL4: -0.055049082 | CM4: -0.018734228 | CN4: 0.011929767 | CO4: 0.053416605 | CP4: -0.084594564 | CQ4: -0.049699512 | CR4: -0.10368528 | CS4: -0.042587626 | CT4: -0.026082052 | CU4: 0.011552788 | CV4: -0.024644621 | CW4: 0.01382821 | CX4: 0.055293579 | CY4: 0.014408657 | CZ4: -0.048467141 | DA4: -0.037626473 | DB4: 0.020116254 | DC4: 0.018995338 | DD4: 0.039237627 | DE4: -0.0045888661 | DF4: -0.046855473 | DG4: -0.0088936271 | DH4: -0.028857627 | DI4: {=SUMPRODUCT(POWER(B4:DH4,2))} -> 1
